Workbook

Sheet Claim
A1: No | B1: Site ID | C1: Pre Approval Cert# | D1: Perbaikan Assets Cert# | E1: Provider | F1: Project Provider | G1: Package | H1: Scope | I1: Material | J1: Quantity | K1: Generated By | L1: Date Created | M1: Current Phase | N1: Overall Status | O1: Pre Approval Status | P1: Request Status | Q1: Perbaikan Assets Status | R1: Rejection Notes | S1: Canceled Notes
A2: 1 | B2: KLT00034 | C2: PRE-APPROVAL-KLAIM-GARANSI/PMO/X/2026/0188 | D2: - | E2: PT Alita Praya Mitra | F2: Kemitraan FH-TI-MTD | G2: Paket 6 | H2: Power | I2: BATERAI | J2: 1 | K2: Bayu Ridho Triutomo | L2: 17-10-2026 15:14 | M2: PRE_APPROVAL | N2: IN_PROGRESS | O2: KSO Pending | P2: - | Q2: - | R2: - | S2: -
A3: 2 | B3: KLT00034 | C3: PRE-APPROVAL-KLAIM-GARANSI/PMO/X/2026/0187 | D3: - | E3: PT Alita Praya Mitra | F3: Kemitraan FH-TI-MTD | G3: Paket 6 | H3: Tower | I3: YARD LAMP | J3: 1 | K3: Bayu Ridho Triutomo | L3: 17-10-2026 14:38 | M3: PRE_APPROVAL | N3: IN_PROGRESS | O3: KSO Pending | P3: - | Q3: - | R3: - | S3: -
A4: 3 | B4: KLT00062 | C4: PRE-APPROVAL-KLAIM-GARANSI/PMO/X/2026/0186 | D4: - | E4: PT Alita Praya Mitra | F4: Kemitraan FH-TI-MTD | G4: Paket 6 | H4: Tower | I4: YARD LAMP | J4: 1 | K4: Bayu Ridho Triutomo | L4: 17-10-2026 14:34 | M4: PRE_APPROVAL | N4: IN_PROGRESS | O4: KSO Pending | P4: - | Q4: - | R4: - | S4: -
A5: 4 | B5: KLT00034 | C5: PRE-APPROVAL-KLAIM-GARANSI/PMO/X/2026/0185 | D5: - | E5: PT Alita Praya Mitra | F5: Kemitraan FH-TI-MTD | G5: Paket 6 | H5: Power | I5: INVERTER 300 W | J5: 1 | K5: Bayu Ridho Triutomo | L5: 17-10-2026 14:19 | M5: PRE_APPROVAL | N5: IN_PROGRESS | O5: KSO Pending | P5: - | Q5: - | R5: - | S5: -
A6: 5 | B6: KLB00387 | C6: PRE-APPROVAL-KLAIM-GARANSI/PMO/X/2026/0184 | D6: - | E6: PT Alita Praya Mitra | F6: Kemitraan FH-TI-MTD | G6: Paket 6 | H6: Transmission | I6: MODEM | J6: 1 | K6: Bayu Ridho Triutomo | L6: 16-10-2026 16:42 | M6: PRE_APPROVAL | N6: IN_PROGRESS | O6: KSO Pending | P6: - | Q6: - | R6: - | S6: -
A7: 6 | B7: KLT0013 | C7: PRE-APPROVAL-KLAIM-GARANSI/PMO/X/2026/0183 | D7: - | E7: PT Alita Praya Mitra | F7: Kemitraan FH-TI-MTD | G7: Paket 6 | H7: Power | I7: INVERTER 300 W | J7: 1 | K7: Bayu Ridho Triutomo | L7: 16-10-2026 16:32 | M7: PRE_APPROVAL | N7: IN_PROGRESS | O7: KSO Pending | P7: - | Q7: - | R7: - | S7: -
A8: 7 | B8: KLB00599 | C8: PRE-APPROVAL-KLAIM-GARANSI/PMO/X/2026/0182 | D8: - | E8: PT Alita Praya Mitra | F8: Kemitraan FH-TI-MTD | G8: Paket 6 | H8: Tower | I8: OBL Lamp | J8: 1 | K8: Bayu Ridho Triutomo | L8: 16-10-2026 16:25 | M8: PRE_APPROVAL | N8: IN_PROGRESS | O8: KSO Pending | P8: - | Q8: - | R8: - | S8: -
A9: 8 | B9: KLB00387 | C9: PRE-APPROVAL-KLAIM-GARANSI/PMO/X/2026/0181 | D9: - | E9: PT Alita Praya Mitra | F9: Kemitraan FH-TI-MTD | G9: Paket 6 | H9: Transmission | I9: BUC | J9: 1 | K9: Bayu Ridho Triutomo | L9: 16-10-2026 14:34 | M9: PRE_APPROVAL | N9: IN_PROGRESS | O9: KSO Pending | P9: - | Q9: - | R9: - | S9: -
A10: 9 | B10: KLT00062 | C10: PRE-APPROVAL-KLAIM-GARANSI/PMO/X/2026/0179 | D10: - | E10: PT Alita Praya Mitra | F10: Kemitraan FH-TI-MTD | G10: Paket 6 | H10: Power | I10: INVERTER 300 W | J10: 1 | K10: Bayu Ridho Triutomo | L10: 16-10-2026 11:31 | M10: PRE_APPROVAL | N10: IN_PROGRESS | O10: KSO Pending | P10: - | Q10: - | R10: - | S10: -
A11: 10 | B11: KLT00050 | C11: PRE-APPROVAL-KLAIM-GARANSI/PMO/X/2026/0178 | D11: - | E11: PT Alita Praya Mitra | F11: Kemitraan FH-TI-MTD | G11: Paket 6 | H11: Power | I11: INVERTER 300 W | J11: 1 | K11: Bayu Ridho Triutomo | L11: 16-10-2026 11:23 | M11: PRE_APPROVAL | N11: IN_PROGRESS | O11: KSO Pending | P11: - | Q11: - | R11: - | S11: -
A12: 11 | B12: KLT00037 | C12: PRE-APPROVAL-KLAIM-GARANSI/PMO/X/2026/0177 | D12: - | E12: PT Alita Praya Mitra | F12: Kemitraan FH-TI-MTD | G12: Paket 6 | H12: Power | I12: INVERTER 300 W | J12: 1 | K12: Bayu Ridho Triutomo | L12: 16-10-2026 11:20 | M12: PRE_APPROVAL | N12: IN_PROGRESS | O12: KSO Pending | P12: - | Q12: - | R12: - | S12: -
A13: 12 | B13: KLT00031 | C13: PRE-APPROVAL-KLAIM-GARANSI/PMO/X/2026/0176 | D13: - | E13: PT Alita Praya Mitra | F13: Kemitraan FH-TI-MTD | G13: Paket 6 | H13: Power | I13: INVERTER 300 W | J13: 1 | K13: Bayu Ridho Triutomo | L13: 16-10-2026 11:08 | M13: PRE_APPROVAL | N13: IN_PROGRESS | O13: KSO Pending | P13: - | Q13: - | R13: - | S13: -
... A106: 105 | B106: KLI00037 | C106: PRE-APPROVAL-KLAIM-GARANSI/PMO/VI/2026/0004 | D106: - | E106: PT Alita Praya Mitra | F106: Kemitraan FH-TI-MTD | G106: Paket 6 | H106: BTS | I106: RRU | J106: 1 | K106: Bayu Ridho Triutomo | L106: 12-06-2026 14:06 | M106: REQUEST_GARANSI | N106: IN_PROGRESS | O106: Approved | P106: MSS Pending Form | Q106: - | R106: - | S106: -

Sheet Manual
A1: Pre Approval Cert# | B1: Site Id | C1: Sitename | D1: Provinsi | E1: Kota/Kab | F1: Latitude | G1: Longitude | H1: Material | I1: Quantity | J1: Current Phase | K1: Pre Approval Status | L1: Request Status | M1: Perbaikan Assets Status | N1: MSS Need Send? | O1: KSO Need Send? | P1: Date Pengiriman MSS | Q1: Status Pengiriman MSS | R1: Date Pengiriman KSO | S1: Status Pengiriman KSO / On hand MSS
A2: PRE-APPROVAL-KLAIM-GARANSI/PMO/X/2026/0188 | B2: KLT00034 | C2: =_xlfn.XLOOKUP(B2,Engpar!A:A,Engpar!C:C) -> RIAM BATANG | D2: =_xlfn.XLOOKUP(B2,Engpar!A:A,Engpar!F:F) -> KALIMANTAN TENGAH | E2: =_xlfn.XLOOKUP(B2,Engpar!A:A,Engpar!G:G) -> SERUYAN | F2: =_xlfn.XLOOKUP(B2,Engpar!A:A,Engpar!J:J) -> -0.86212 | G2: =_xlfn.XLOOKUP(B2,Engpar!A:A,Engpar!K:K) -> 112.08057 | H2: =_xlfn.XLOOKUP(A2,Claim!C:C,Claim!I:I) -> BATERAI | I2: =_xlfn.XLOOKUP(A2,Claim!C:C,Claim!J:J) -> 1 | J2: =_xlfn.XLOOKUP(A2,Claim!C:C,Claim!M:M) -> PRE_APPROVAL | K2: =_xlfn.XLOOKUP(A2,Claim!C:C,Claim!O:O) -> KSO Pending | L2: =_xlfn.XLOOKUP(A2,Claim!C:C,Claim!P:P) -> - | M2: =_xlfn.XLOOKUP(A2,Claim!C:C,Claim!Q:Q) -> - | N2: {=_xlfn.IFS( OR(L2="Cancel", L2="Canceled", L2="Reject", L2="Rejected"), "Cancel / Rejected", AND(OR(J2="Request_Garansi", J2="Perbaikan_Asset"), OR(L2="Approved", L2="PMO Pending")), "MSS Need Send", TRUE, "Waiting Approval" )} -> Waiting Approval | O2: {=_xlfn.IFS( OR(M2="Cancel", M2="Canceled", M2="Reject", M2="Rejected", K2="Cancel", K2="Canceled", K2="Reject", K2="Rejected", L2="Cancel", L2="Canceled", L2="Reject", L2="Rejected"), "Cancel / Rejected", AND(OR(J2="Perbaikan_Asset"), OR(M2="KSO Pending")), "KSO Need Send", TRUE, "Waiting Approval" )} -> Waiting Approval | Q2: {=_xlfn.IFS( OR(M2="Cancel", M2="Canceled", M2="Reject", M2="Rejected", K2="Cancel", K2="Canceled", K2="Reject", K2="Rejected", L2="Cancel", L2="Canceled", L2="Reject", L2="Rejected"), "Cancel / Rejected", P2<>"", "MSS Done Send", N2="MSS Need Send", "MSS Need Send", TRUE, "Waiting Approval" )} -> Waiting Approval | S2: {=_xlfn.IFS( OR(M2="Cancel", M2="Canceled", M2="Reject", M2="Rejected", K2="Cancel", K2="Canceled", K2="Reject", K2="Rejected", L2="Cancel", L2="Canceled", L2="Reject", L2="Rejected"), "Cancel / Rejected", R2<>"", "KSO Done Send", Q2="MSS Need Send", "MSS Need Send", O2="KSO Need Send", "KSO Need Send", TRUE, "Waiting Approval" )} -> Waiting Approval
A3: PRE-APPROVAL-KLAIM-GARANSI/PMO/X/2026/0187 | B3: KLT00034 | C3: =_xlfn.XLOOKUP(B3,Engpar!A:A,Engpar!C:C) -> RIAM BATANG | D3: =_xlfn.XLOOKUP(B3,Engpar!A:A,Engpar!F:F) -> KALIMANTAN TENGAH | E3: =_xlfn.XLOOKUP(B3,Engpar!A:A,Engpar!G:G) -> SERUYAN | F3: =_xlfn.XLOOKUP(B3,Engpar!A:A,Engpar!J:J) -> -0.86212 | G3: =_xlfn.XLOOKUP(B3,Engpar!A:A,Engpar!K:K) -> 112.08057 | H3: =_xlfn.XLOOKUP(A3,Claim!C:C,Claim!I:I) -> YARD LAMP | I3: =_xlfn.XLOOKUP(A3,Claim!C:C,Claim!J:J) -> 1 | J3: =_xlfn.XLOOKUP(A3,Claim!C:C,Claim!M:M) -> PRE_APPROVAL | K3: =_xlfn.XLOOKUP(A3,Claim!C:C,Claim!O:O) -> KSO Pending | L3: =_xlfn.XLOOKUP(A3,Claim!C:C,Claim!P:P) -> - | M3: =_xlfn.XLOOKUP(A3,Claim!C:C,Claim!Q:Q) -> - | N3: {=_xlfn.IFS( OR(L3="Cancel", L3="Canceled", L3="Reject", L3="Rejected"), "Cancel / Rejected", AND(OR(J3="Request_Garansi", J3="Perbaikan_Asset"), OR(L3="Approved", L3="PMO Pending")), "MSS Need Send", TRUE, "Waiting Approval" )} -> Waiting Approval | O3: {=_xlfn.IFS( OR(M3="Cancel", M3="Canceled", M3="Reject", M3="Rejected", K3="Cancel", K3="Canceled", K3="Reject", K3="Rejected", L3="Cancel", L3="Canceled", L3="Reject", L3="Rejected"), "Cancel / Rejected", AND(OR(J3="Perbaikan_Asset"), OR(M3="KSO Pending")), "KSO Need Send", TRUE, "Waiting Approval" )} -> Waiting Approval | Q3: {=_xlfn.IFS( OR(M3="Cancel", M3="Canceled", M3="Reject", M3="Rejected", K3="Cancel", K3="Canceled", K3="Reject", K3="Rejected", L3="Cancel", L3="Canceled", L3="Reject", L3="Rejected"), "Cancel / Rejected", P3<>"", "MSS Done Send", N3="MSS Need Send", "MSS Need Send", TRUE, "Waiting Approval" )} -> Waiting Approval | S3: {=_xlfn.IFS( OR(M3="Cancel", M3="Canceled", M3="Reject", M3="Rejected", K3="Cancel", K3="Canceled", K3="Reject", K3="Rejected", L3="Cancel", L3="Canceled", L3="Reject", L3="Rejected"), "Cancel / Rejected", R3<>"", "KSO Done Send", Q3="MSS Need Send", "MSS Need Send", O3="KSO Need Send", "KSO Need Send", TRUE, "Waiting Approval" )} -> Waiting Approval
A4: PRE-APPROVAL-KLAIM-GARANSI/PMO/X/2026/0186 | B4: KLT00062 | C4: =_xlfn.XLOOKUP(B4,Engpar!A:A,Engpar!C:C) -> RANTAU SUANG | D4: =_xlfn.XLOOKUP(B4,Engpar!A:A,Engpar!F:F) -> KALIMANTAN TENGAH | E4: =_xlfn.XLOOKUP(B4,Engpar!A:A,Engpar!G:G) -> KOTAWARINGIN TIMUR | F4: =_xlfn.XLOOKUP(B4,Engpar!A:A,Engpar!J:J) -> -1.46858 | G4: =_xlfn.XLOOKUP(B4,Engpar!A:A,Engpar!K:K) -> 112.28144 | H4: =_xlfn.XLOOKUP(A4,Claim!C:C,Claim!I:I) -> YARD LAMP | I4: =_xlfn.XLOOKUP(A4,Claim!C:C,Claim!J:J) -> 1 | J4: =_xlfn.XLOOKUP(A4,Claim!C:C,Claim!M:M) -> PRE_APPROVAL | K4: =_xlfn.XLOOKUP(A4,Claim!C:C,Claim!O:O) -> KSO Pending | L4: =_xlfn.XLOOKUP(A4,Claim!C:C,Claim!P:P) -> - | M4: =_xlfn.XLOOKUP(A4,Claim!C:C,Claim!Q:Q) -> - | N4: {=_xlfn.IFS( OR(L4="Cancel", L4="Canceled", L4="Reject", L4="Rejected"), "Cancel / Rejected", AND(OR(J4="Request_Garansi", J4="Perbaikan_Asset"), OR(L4="Approved", L4="PMO Pending")), "MSS Need Send", TRUE, "Waiting Approval" )} -> Waiting Approval | O4: {=_xlfn.IFS( OR(M4="Cancel", M4="Canceled", M4="Reject", M4="Rejected", K4="Cancel", K4="Canceled", K4="Reject", K4="Rejected", L4="Cancel", L4="Canceled", L4="Reject", L4="Rejected"), "Cancel / Rejected", AND(OR(J4="Perbaikan_Asset"), OR(M4="KSO Pending")), "KSO Need Send", TRUE, "Waiting Approval" )} -> Waiting Approval | Q4: {=_xlfn.IFS( OR(M4="Cancel", M4="Canceled", M4="Reject", M4="Rejected", K4="Cancel", K4="Canceled", K4="Reject", K4="Rejected", L4="Cancel", L4="Canceled", L4="Reject", L4="Rejected"), "Cancel / Rejected", P4<>"", "MSS Done Send", N4="MSS Need Send", "MSS Need Send", TRUE, "Waiting Approval" )} -> Waiting Approval | S4: {=_xlfn.IFS( OR(M4="Cancel", M4="Canceled", M4="Reject", M4="Rejected", K4="Cancel", K4="Canceled", K4="Reject", K4="Rejected", L4="Cancel", L4="Canceled", L4="Reject", L4="Rejected"), "Cancel / Rejected", R4<>"", "KSO Done Send", Q4="MSS Need Send", "MSS Need Send", O4="KSO Need Send", "KSO Need Send", TRUE, "Waiting Approval" )} -> Waiting Approval
A5: PRE-APPROVAL-KLAIM-GARANSI/PMO/X/2026/0185 | B5: KLT00034 | C5: =_xlfn.XLOOKUP(B5,Engpar!A:A,Engpar!C:C) -> RIAM BATANG | D5: =_xlfn.XLOOKUP(B5,Engpar!A:A,Engpar!F:F) -> KALIMANTAN TENGAH | E5: =_xlfn.XLOOKUP(B5,Engpar!A:A,Engpar!G:G) -> SERUYAN | F5: =_xlfn.XLOOKUP(B5,Engpar!A:A,Engpar!J:J) -> -0.86212 | G5: =_xlfn.XLOOKUP(B5,Engpar!A:A,Engpar!K:K) -> 112.08057 | H5: =_xlfn.XLOOKUP(A5,Claim!C:C,Claim!I:I) -> INVERTER 300 W | I5: =_xlfn.XLOOKUP(A5,Claim!C:C,Claim!J:J) -> 1 | J5: =_xlfn.XLOOKUP(A5,Claim!C:C,Claim!M:M) -> PRE_APPROVAL | K5: =_xlfn.XLOOKUP(A5,Claim!C:C,Claim!O:O) -> KSO Pending | L5: =_xlfn.XLOOKUP(A5,Claim!C:C,Claim!P:P) -> - | M5: =_xlfn.XLOOKUP(A5,Claim!C:C,Claim!Q:Q) -> - | N5: {=_xlfn.IFS( OR(L5="Cancel", L5="Canceled", L5="Reject", L5="Rejected"), "Cancel / Rejected", AND(OR(J5="Request_Garansi", J5="Perbaikan_Asset"), OR(L5="Approved", L5="PMO Pending")), "MSS Need Send", TRUE, "Waiting Approval" )} -> Waiting Approval | O5: {=_xlfn.IFS( OR(M5="Cancel", M5="Canceled", M5="Reject", M5="Rejected", K5="Cancel", K5="Canceled", K5="Reject", K5="Rejected", L5="Cancel", L5="Canceled", L5="Reject", L5="Rejected"), "Cancel / Rejected", AND(OR(J5="Perbaikan_Asset"), OR(M5="KSO Pending")), "KSO Need Send", TRUE, "Waiting Approval" )} -> Waiting Approval | Q5: {=_xlfn.IFS( OR(M5="Cancel", M5="Canceled", M5="Reject", M5="Rejected", K5="Cancel", K5="Canceled", K5="Reject", K5="Rejected", L5="Cancel", L5="Canceled", L5="Reject", L5="Rejected"), "Cancel / Rejected", P5<>"", "MSS Done Send", N5="MSS Need Send", "MSS Need Send", TRUE, "Waiting Approval" )} -> Waiting Approval | S5: {=_xlfn.IFS( OR(M5="Cancel", M5="Canceled", M5="Reject", M5="Rejected", K5="Cancel", K5="Canceled", K5="Reject", K5="Rejected", L5="Cancel", L5="Canceled", L5="Reject", L5="Rejected"), "Cancel / Rejected", R5<>"", "KSO Done Send", Q5="MSS Need Send", "MSS Need Send", O5="KSO Need Send", "KSO Need Send", TRUE, "Waiting Approval" )} -> Waiting Approval
A6: PRE-APPROVAL-KLAIM-GARANSI/PMO/X/2026/0184 | B6: KLB00387 | C6: =_xlfn.XLOOKUP(B6,Engpar!A:A,Engpar!C:C) -> LAUT TAWANG | D6: =_xlfn.XLOOKUP(B6,Engpar!A:A,Engpar!F:F) -> KALIMANTAN BARAT | E6: =_xlfn.XLOOKUP(B6,Engpar!A:A,Engpar!G:G) -> KAPUAS HULU | F6: =_xlfn.XLOOKUP(B6,Engpar!A:A,Engpar!J:J) -> 0.74492 | G6: =_xlfn.XLOOKUP(B6,Engpar!A:A,Engpar!K:K) -> 111.96001 | H6: =_xlfn.XLOOKUP(A6,Claim!C:C,Claim!I:I) -> MODEM | I6: =_xlfn.XLOOKUP(A6,Claim!C:C,Claim!J:J) -> 1 | J6: =_xlfn.XLOOKUP(A6,Claim!C:C,Claim!M:M) -> PRE_APPROVAL | K6: =_xlfn.XLOOKUP(A6,Claim!C:C,Claim!O:O) -> KSO Pending | L6: =_xlfn.XLOOKUP(A6,Claim!C:C,Claim!P:P) -> - | M6: =_xlfn.XLOOKUP(A6,Claim!C:C,Claim!Q:Q) -> - | N6: {=_xlfn.IFS( OR(L6="Cancel", L6="Canceled", L6="Reject", L6="Rejected"), "Cancel / Rejected", AND(OR(J6="Request_Garansi", J6="Perbaikan_Asset"), OR(L6="Approved", L6="PMO Pending")), "MSS Need Send", TRUE, "Waiting Approval" )} -> Waiting Approval | O6: {=_xlfn.IFS( OR(M6="Cancel", M6="Canceled", M6="Reject", M6="Rejected", K6="Cancel", K6="Canceled", K6="Reject", K6="Rejected", L6="Cancel", L6="Canceled", L6="Reject", L6="Rejected"), "Cancel / Rejected", AND(OR(J6="Perbaikan_Asset"), OR(M6="KSO Pending")), "KSO Need Send", TRUE, "Waiting Approval" )} -> Waiting Approval | Q6: {=_xlfn.IFS( OR(M6="Cancel", M6="Canceled", M6="Reject", M6="Rejected", K6="Cancel", K6="Canceled", K6="Reject", K6="Rejected", L6="Cancel", L6="Canceled", L6="Reject", L6="Rejected"), "Cancel / Rejected", P6<>"", "MSS Done Send", N6="MSS Need Send", "MSS Need Send", TRUE, "Waiting Approval" )} -> Waiting Approval | S6: {=_xlfn.IFS( OR(M6="Cancel", M6="Canceled", M6="Reject", M6="Rejected", K6="Cancel", K6="Canceled", K6="Reject", K6="Rejected", L6="Cancel", L6="Canceled", L6="Reject", L6="Rejected"), "Cancel / Rejected", R6<>"", "KSO Done Send", Q6="MSS Need Send", "MSS Need Send", O6="KSO Need Send", "KSO Need Send", TRUE, "Waiting Approval" )} -> Waiting Approval
A7: PRE-APPROVAL-KLAIM-GARANSI/PMO/X/2026/0183 | B7: KLT0013 | C7: =_xlfn.XLOOKUP(B7,Engpar!A:A,Engpar!C:C) -> TUMBANG SEPAN | D7: =_xlfn.XLOOKUP(B7,Engpar!A:A,Engpar!F:F) -> KALIMANTAN TENGAH | E7: =_xlfn.XLOOKUP(B7,Engpar!A:A,Engpar!G:G) -> SERUYAN | F7: =_xlfn.XLOOKUP(B7,Engpar!A:A,Engpar!J:J) -> -0.90825 | G7: =_xlfn.XLOOKUP(B7,Engpar!A:A,Engpar!K:K) -> 112.06332 | H7: =_xlfn.XLOOKUP(A7,Claim!C:C,Claim!I:I) -> INVERTER 300 W | I7: =_xlfn.XLOOKUP(A7,Claim!C:C,Claim!J:J) -> 1 | J7: =_xlfn.XLOOKUP(A7,Claim!C:C,Claim!M:M) -> PRE_APPROVAL | K7: =_xlfn.XLOOKUP(A7,Claim!C:C,Claim!O:O) -> KSO Pending | L7: =_xlfn.XLOOKUP(A7,Claim!C:C,Claim!P:P) -> - | M7: =_xlfn.XLOOKUP(A7,Claim!C:C,Claim!Q:Q) -> - | N7: {=_xlfn.IFS( OR(L7="Cancel", L7="Canceled", L7="Reject", L7="Rejected"), "Cancel / Rejected", AND(OR(J7="Request_Garansi", J7="Perbaikan_Asset"), OR(L7="Approved", L7="PMO Pending")), "MSS Need Send", TRUE, "Waiting Approval" )} -> Waiting Approval | O7: {=_xlfn.IFS( OR(M7="Cancel", M7="Canceled", M7="Reject", M7="Rejected", K7="Cancel", K7="Canceled", K7="Reject", K7="Rejected", L7="Cancel", L7="Canceled", L7="Reject", L7="Rejected"), "Cancel / Rejected", AND(OR(J7="Perbaikan_Asset"), OR(M7="KSO Pending")), "KSO Need Send", TRUE, "Waiting Approval" )} -> Waiting Approval | Q7: {=_xlfn.IFS( OR(M7="Cancel", M7="Canceled", M7="Reject", M7="Rejected", K7="Cancel", K7="Canceled", K7="Reject", K7="Rejected", L7="Cancel", L7="Canceled", L7="Reject", L7="Rejected"), "Cancel / Rejected", P7<>"", "MSS Done Send", N7="MSS Need Send", "MSS Need Send", TRUE, "Waiting Approval" )} -> Waiting Approval | S7: {=_xlfn.IFS( OR(M7="Cancel", M7="Canceled", M7="Reject", M7="Rejected", K7="Cancel", K7="Canceled", K7="Reject", K7="Rejected", L7="Cancel", L7="Canceled", L7="Reject", L7="Rejected"), "Cancel / Rejected", R7<>"", "KSO Done Send", Q7="MSS Need Send", "MSS Need Send", O7="KSO Need Send", "KSO Need Send", TRUE, "Waiting Approval" )} -> Waiting Approval
A8: PRE-APPROVAL-KLAIM-GARANSI/PMO/X/2026/0182 | B8: KLB00599 | C8: =_xlfn.XLOOKUP(B8,Engpar!A:A,Engpar!C:C) -> SAHAM | D8: =_xlfn.XLOOKUP(B8,Engpar!A:A,Engpar!F:F) -> KALIMANTAN BARAT | E8: =_xlfn.XLOOKUP(B8,Engpar!A:A,Engpar!G:G) -> LANDAK | F8: =_xlfn.XLOOKUP(B8,Engpar!A:A,Engpar!J:J) -> 0.24271 | G8: =_xlfn.XLOOKUP(B8,Engpar!A:A,Engpar!K:K) -> 109.68005 | H8: =_xlfn.XLOOKUP(A8,Claim!C:C,Claim!I:I) -> OBL Lamp | I8: =_xlfn.XLOOKUP(A8,Claim!C:C,Claim!J:J) -> 1 | J8: =_xlfn.XLOOKUP(A8,Claim!C:C,Claim!M:M) -> PRE_APPROVAL | K8: =_xlfn.XLOOKUP(A8,Claim!C:C,Claim!O:O) -> KSO Pending | L8: =_xlfn.XLOOKUP(A8,Claim!C:C,Claim!P:P) -> - | M8: =_xlfn.XLOOKUP(A8,Claim!C:C,Claim!Q:Q) -> - | N8: {=_xlfn.IFS( OR(L8="Cancel", L8="Canceled", L8="Reject", L8="Rejected"), "Cancel / Rejected", AND(OR(J8="Request_Garansi", J8="Perbaikan_Asset"), OR(L8="Approved", L8="PMO Pending")), "MSS Need Send", TRUE, "Waiting Approval" )} -> Waiting Approval | O8: {=_xlfn.IFS( OR(M8="Cancel", M8="Canceled", M8="Reject", M8="Rejected", K8="Cancel", K8="Canceled", K8="Reject", K8="Rejected", L8="Cancel", L8="Canceled", L8="Reject", L8="Rejected"), "Cancel / Rejected", AND(OR(J8="Perbaikan_Asset"), OR(M8="KSO Pending")), "KSO Need Send", TRUE, "Waiting Approval" )} -> Waiting Approval | Q8: {=_xlfn.IFS( OR(M8="Cancel", M8="Canceled", M8="Reject", M8="Rejected", K8="Cancel", K8="Canceled", K8="Reject", K8="Rejected", L8="Cancel", L8="Canceled", L8="Reject", L8="Rejected"), "Cancel / Rejected", P8<>"", "MSS Done Send", N8="MSS Need Send", "MSS Need Send", TRUE, "Waiting Approval" )} -> Waiting Approval | S8: {=_xlfn.IFS( OR(M8="Cancel", M8="Canceled", M8="Reject", M8="Rejected", K8="Cancel", K8="Canceled", K8="Reject", K8="Rejected", L8="Cancel", L8="Canceled", L8="Reject", L8="Rejected"), "Cancel / Rejected", R8<>"", "KSO Done Send", Q8="MSS Need Send", "MSS Need Send", O8="KSO Need Send", "KSO Need Send", TRUE, "Waiting Approval" )} -> Waiting Approval
A9: PRE-APPROVAL-KLAIM-GARANSI/PMO/X/2026/0181 | B9: KLB00387 | C9: =_xlfn.XLOOKUP(B9,Engpar!A:A,Engpar!C:C) -> LAUT TAWANG | D9: =_xlfn.XLOOKUP(B9,Engpar!A:A,Engpar!F:F) -> KALIMANTAN BARAT | E9: =_xlfn.XLOOKUP(B9,Engpar!A:A,Engpar!G:G) -> KAPUAS HULU | F9: =_xlfn.XLOOKUP(B9,Engpar!A:A,Engpar!J:J) -> 0.74492 | G9: =_xlfn.XLOOKUP(B9,Engpar!A:A,Engpar!K:K) -> 111.96001 | H9: =_xlfn.XLOOKUP(A9,Claim!C:C,Claim!I:I) -> BUC | I9: =_xlfn.XLOOKUP(A9,Claim!C:C,Claim!J:J) -> 1 | J9: =_xlfn.XLOOKUP(A9,Claim!C:C,Claim!M:M) -> PRE_APPROVAL | K9: =_xlfn.XLOOKUP(A9,Claim!C:C,Claim!O:O) -> KSO Pending | L9: =_xlfn.XLOOKUP(A9,Claim!C:C,Claim!P:P) -> - | M9: =_xlfn.XLOOKUP(A9,Claim!C:C,Claim!Q:Q) -> - | N9: {=_xlfn.IFS( OR(L9="Cancel", L9="Canceled", L9="Reject", L9="Rejected"), "Cancel / Rejected", AND(OR(J9="Request_Garansi", J9="Perbaikan_Asset"), OR(L9="Approved", L9="PMO Pending")), "MSS Need Send", TRUE, "Waiting Approval" )} -> Waiting Approval | O9: {=_xlfn.IFS( OR(M9="Cancel", M9="Canceled", M9="Reject", M9="Rejected", K9="Cancel", K9="Canceled", K9="Reject", K9="Rejected", L9="Cancel", L9="Canceled", L9="Reject", L9="Rejected"), "Cancel / Rejected", AND(OR(J9="Perbaikan_Asset"), OR(M9="KSO Pending")), "KSO Need Send", TRUE, "Waiting Approval" )} -> Waiting Approval | Q9: {=_xlfn.IFS( OR(M9="Cancel", M9="Canceled", M9="Reject", M9="Rejected", K9="Cancel", K9="Canceled", K9="Reject", K9="Rejected", L9="Cancel", L9="Canceled", L9="Reject", L9="Rejected"), "Cancel / Rejected", P9<>"", "MSS Done Send", N9="MSS Need Send", "MSS Need Send", TRUE, "Waiting Approval" )} -> Waiting Approval | S9: {=_xlfn.IFS( OR(M9="Cancel", M9="Canceled", M9="Reject", M9="Rejected", K9="Cancel", K9="Canceled", K9="Reject", K9="Rejected", L9="Cancel", L9="Canceled", L9="Reject", L9="Rejected"), "Cancel / Rejected", R9<>"", "KSO Done Send", Q9="MSS Need Send", "MSS Need Send", O9="KSO Need Send", "KSO Need Send", TRUE, "Waiting Approval" )} -> Waiting Approval
A10: PRE-APPROVAL-KLAIM-GARANSI/PMO/X/2026/0179 | B10: KLT00062 | C10: =_xlfn.XLOOKUP(B10,Engpar!A:A,Engpar!C:C) -> RANTAU SUANG | D10: =_xlfn.XLOOKUP(B10,Engpar!A:A,Engpar!F:F) -> KALIMANTAN TENGAH | E10: =_xlfn.XLOOKUP(B10,Engpar!A:A,Engpar!G:G) -> KOTAWARINGIN TIMUR | F10: =_xlfn.XLOOKUP(B10,Engpar!A:A,Engpar!J:J) -> -1.46858 | G10: =_xlfn.XLOOKUP(B10,Engpar!A:A,Engpar!K:K) -> 112.28144 | H10: =_xlfn.XLOOKUP(A10,Claim!C:C,Claim!I:I) -> INVERTER 300 W | I10: =_xlfn.XLOOKUP(A10,Claim!C:C,Claim!J:J) -> 1 | J10: =_xlfn.XLOOKUP(A10,Claim!C:C,Claim!M:M) -> PRE_APPROVAL | K10: =_xlfn.XLOOKUP(A10,Claim!C:C,Claim!O:O) -> KSO Pending | L10: =_xlfn.XLOOKUP(A10,Claim!C:C,Claim!P:P) -> - | M10: =_xlfn.XLOOKUP(A10,Claim!C:C,Claim!Q:Q) -> - | N10: {=_xlfn.IFS( OR(L10="Cancel", L10="Canceled", L10="Reject", L10="Rejected"), "Cancel / Rejected", AND(OR(J10="Request_Garansi", J10="Perbaikan_Asset"), OR(L10="Approved", L10="PMO Pending")), "MSS Need Send", TRUE, "Waiting Approval" )} -> Waiting Approval | O10: {=_xlfn.IFS( OR(M10="Cancel", M10="Canceled", M10="Reject", M10="Rejected", K10="Cancel", K10="Canceled", K10="Reject", K10="Rejected", L10="Cancel", L10="Canceled", L10="Reject", L10="Rejected"), "Cancel / Rejected", AND(OR(J10="Perbaikan_Asset"), OR(M10="KSO Pending")), "KSO Need Send", TRUE, "Waiting Approval" )} -> Waiting Approval | Q10: {=_xlfn.IFS( OR(M10="Cancel", M10="Canceled", M10="Reject", M10="Rejected", K10="Cancel", K10="Canceled", K10="Reject", K10="Rejected", L10="Cancel", L10="Canceled", L10="Reject", L10="Rejected"), "Cancel / Rejected", P10<>"", "MSS Done Send", N10="MSS Need Send", "MSS Need Send", TRUE, "Waiting Approval" )} -> Waiting Approval | S10: {=_xlfn.IFS( OR(M10="Cancel", M10="Canceled", M10="Reject", M10="Rejected", K10="Cancel", K10="Canceled", K10="Reject", K10="Rejected", L10="Cancel", L10="Canceled", L10="Reject", L10="Rejected"), "Cancel / Rejected", R10<>"", "KSO Done Send", Q10="MSS Need Send", "MSS Need Send", O10="KSO Need Send", "KSO Need Send", TRUE, "Waiting Approval" )} -> Waiting Approval
A11: PRE-APPROVAL-KLAIM-GARANSI/PMO/X/2026/0178 | B11: KLT00050 | C11: =_xlfn.XLOOKUP(B11,Engpar!A:A,Engpar!C:C) -> BATU BADAK | D11: =_xlfn.XLOOKUP(B11,Engpar!A:A,Engpar!F:F) -> KALIMANTAN TENGAH | E11: =_xlfn.XLOOKUP(B11,Engpar!A:A,Engpar!G:G) -> KATINGAN | F11: =_xlfn.XLOOKUP(B11,Engpar!A:A,Engpar!J:J) -> -0.99502 | G11: =_xlfn.XLOOKUP(B11,Engpar!A:A,Engpar!K:K) -> 112.92697 | H11: =_xlfn.XLOOKUP(A11,Claim!C:C,Claim!I:I) -> INVERTER 300 W | I11: =_xlfn.XLOOKUP(A11,Claim!C:C,Claim!J:J) -> 1 | J11: =_xlfn.XLOOKUP(A11,Claim!C:C,Claim!M:M) -> PRE_APPROVAL | K11: =_xlfn.XLOOKUP(A11,Claim!C:C,Claim!O:O) -> KSO Pending | L11: =_xlfn.XLOOKUP(A11,Claim!C:C,Claim!P:P) -> - | M11: =_xlfn.XLOOKUP(A11,Claim!C:C,Claim!Q:Q) -> - | N11: {=_xlfn.IFS( OR(L11="Cancel", L11="Canceled", L11="Reject", L11="Rejected"), "Cancel / Rejected", AND(OR(J11="Request_Garansi", J11="Perbaikan_Asset"), OR(L11="Approved", L11="PMO Pending")), "MSS Need Send", TRUE, "Waiting Approval" )} -> Waiting Approval | O11: {=_xlfn.IFS( OR(M11="Cancel", M11="Canceled", M11="Reject", M11="Rejected", K11="Cancel", K11="Canceled", K11="Reject", K11="Rejected", L11="Cancel", L11="Canceled", L11="Reject", L11="Rejected"), "Cancel / Rejected", AND(OR(J11="Perbaikan_Asset"), OR(M11="KSO Pending")), "KSO Need Send", TRUE, "Waiting Approval" )} -> Waiting Approval | Q11: {=_xlfn.IFS( OR(M11="Cancel", M11="Canceled", M11="Reject", M11="Rejected", K11="Cancel", K11="Canceled", K11="Reject", K11="Rejected", L11="Cancel", L11="Canceled", L11="Reject", L11="Rejected"), "Cancel / Rejected", P11<>"", "MSS Done Send", N11="MSS Need Send", "MSS Need Send", TRUE, "Waiting Approval" )} -> Waiting Approval | S11: {=_xlfn.IFS( OR(M11="Cancel", M11="Canceled", M11="Reject", M11="Rejected", K11="Cancel", K11="Canceled", K11="Reject", K11="Rejected", L11="Cancel", L11="Canceled", L11="Reject", L11="Rejected"), "Cancel / Rejected", R11<>"", "KSO Done Send", Q11="MSS Need Send", "MSS Need Send", O11="KSO Need Send", "KSO Need Send", TRUE, "Waiting Approval" )} -> Waiting Approval
A12: PRE-APPROVAL-KLAIM-GARANSI/PMO/X/2026/0177 | B12: KLT00037 | C12: =_xlfn.XLOOKUP(B12,Engpar!A:A,Engpar!C:C) -> TUMBANG TANGOI | D12: =_xlfn.XLOOKUP(B12,Engpar!A:A,Engpar!F:F) -> KALIMANTAN TENGAH | E12: =_xlfn.XLOOKUP(B12,Engpar!A:A,Engpar!G:G) -> KATINGAN | F12: =_xlfn.XLOOKUP(B12,Engpar!A:A,Engpar!J:J) -> -0.94374 | G12: =_xlfn.XLOOKUP(B12,Engpar!A:A,Engpar!K:K) -> 113.09321 | H12: =_xlfn.XLOOKUP(A12,Claim!C:C,Claim!I:I) -> INVERTER 300 W | I12: =_xlfn.XLOOKUP(A12,Claim!C:C,Claim!J:J) -> 1 | J12: =_xlfn.XLOOKUP(A12,Claim!C:C,Claim!M:M) -> PRE_APPROVAL | K12: =_xlfn.XLOOKUP(A12,Claim!C:C,Claim!O:O) -> KSO Pending | L12: =_xlfn.XLOOKUP(A12,Claim!C:C,Claim!P:P) -> - | M12: =_xlfn.XLOOKUP(A12,Claim!C:C,Claim!Q:Q) -> - | N12: {=_xlfn.IFS( OR(L12="Cancel", L12="Canceled", L12="Reject", L12="Rejected"), "Cancel / Rejected", AND(OR(J12="Request_Garansi", J12="Perbaikan_Asset"), OR(L12="Approved", L12="PMO Pending")), "MSS Need Send", TRUE, "Waiting Approval" )} -> Waiting Approval | O12: {=_xlfn.IFS( OR(M12="Cancel", M12="Canceled", M12="Reject", M12="Rejected", K12="Cancel", K12="Canceled", K12="Reject", K12="Rejected", L12="Cancel", L12="Canceled", L12="Reject", L12="Rejected"), "Cancel / Rejected", AND(OR(J12="Perbaikan_Asset"), OR(M12="KSO Pending")), "KSO Need Send", TRUE, "Waiting Approval" )} -> Waiting Approval | Q12: {=_xlfn.IFS( OR(M12="Cancel", M12="Canceled", M12="Reject", M12="Rejected", K12="Cancel", K12="Canceled", K12="Reject", K12="Rejected", L12="Cancel", L12="Canceled", L12="Reject", L12="Rejected"), "Cancel / Rejected", P12<>"", "MSS Done Send", N12="MSS Need Send", "MSS Need Send", TRUE, "Waiting Approval" )} -> Waiting Approval | S12: {=_xlfn.IFS( OR(M12="Cancel", M12="Canceled", M12="Reject", M12="Rejected", K12="Cancel", K12="Canceled", K12="Reject", K12="Rejected", L12="Cancel", L12="Canceled", L12="Reject", L12="Rejected"), "Cancel / Rejected", R12<>"", "KSO Done Send", Q12="MSS Need Send", "MSS Need Send", O12="KSO Need Send", "KSO Need Send", TRUE, "Waiting Approval" )} -> Waiting Approval
A13: PRE-APPROVAL-KLAIM-GARANSI/PMO/X/2026/0176 | B13: KLT00031 | C13: =_xlfn.XLOOKUP(B13,Engpar!A:A,Engpar!C:C) -> TUMBANG SALAU | D13: =_xlfn.XLOOKUP(B13,Engpar!A:A,Engpar!F:F) -> KALIMANTAN TENGAH | E13: =_xlfn.XLOOKUP(B13,Engpar!A:A,Engpar!G:G) -> SERUYAN | F13: =_xlfn.XLOOKUP(B13,Engpar!A:A,Engpar!J:J) -> -1.29765 | G13: =_xlfn.XLOOKUP(B13,Engpar!A:A,Engpar!K:K) -> 111.81195 | H13: =_xlfn.XLOOKUP(A13,Claim!C:C,Claim!I:I) -> INVERTER 300 W | I13: =_xlfn.XLOOKUP(A13,Claim!C:C,Claim!J:J) -> 1 | J13: =_xlfn.XLOOKUP(A13,Claim!C:C,Claim!M:M) -> PRE_APPROVAL | K13: =_xlfn.XLOOKUP(A13,Claim!C:C,Claim!O:O) -> KSO Pending | L13: =_xlfn.XLOOKUP(A13,Claim!C:C,Claim!P:P) -> - | M13: =_xlfn.XLOOKUP(A13,Claim!C:C,Claim!Q:Q) -> - | N13: {=_xlfn.IFS( OR(L13="Cancel", L13="Canceled", L13="Reject", L13="Rejected"), "Cancel / Rejected", AND(OR(J13="Request_Garansi", J13="Perbaikan_Asset"), OR(L13="Approved", L13="PMO Pending")), "MSS Need Send", TRUE, "Waiting Approval" )} -> Waiting Approval | O13: {=_xlfn.IFS( OR(M13="Cancel", M13="Canceled", M13="Reject", M13="Rejected", K13="Cancel", K13="Canceled", K13="Reject", K13="Rejected", L13="Cancel", L13="Canceled", L13="Reject", L13="Rejected"), "Cancel / Rejected", AND(OR(J13="Perbaikan_Asset"), OR(M13="KSO Pending")), "KSO Need Send", TRUE, "Waiting Approval" )} -> Waiting Approval | Q13: {=_xlfn.IFS( OR(M13="Cancel", M13="Canceled", M13="Reject", M13="Rejected", K13="Cancel", K13="Canceled", K13="Reject", K13="Rejected", L13="Cancel", L13="Canceled", L13="Reject", L13="Rejected"), "Cancel / Rejected", P13<>"", "MSS Done Send", N13="MSS Need Send", "MSS Need Send", TRUE, "Waiting Approval" )} -> Waiting Approval | S13: {=_xlfn.IFS( OR(M13="Cancel", M13="Canceled", M13="Reject", M13="Rejected", K13="Cancel", K13="Canceled", K13="Reject", K13="Rejected", L13="Cancel", L13="Canceled", L13="Reject", L13="Rejected"), "Cancel / Rejected", R13<>"", "KSO Done Send", Q13="MSS Need Send", "MSS Need Send", O13="KSO Need Send", "KSO Need Send", TRUE, "Waiting Approval" )} -> Waiting Approval
... A37: PRE-APPROVAL-KLAIM-GARANSI/PMO/X/2026/0043 | B37: KLT00030 | C37: =_xlfn.XLOOKUP(B37,Engpar!A:A,Engpar!C:C) -> DERAWA | D37: =_xlfn.XLOOKUP(B37,Engpar!A:A,Engpar!F:F) -> KALIMANTAN TENGAH | E37: =_xlfn.XLOOKUP(B37,Engpar!A:A,Engpar!G:G) -> SERUYAN | F37: =_xlfn.XLOOKUP(B37,Engpar!A:A,Engpar!J:J) -> -2.14777 | G37: =_xlfn.XLOOKUP(B37,Engpar!A:A,Engpar!K:K) -> 112.16604 | H37: =_xlfn.XLOOKUP(A37,Claim!C:C,Claim!I:I) -> INVERTER 300 W | I37: =_xlfn.XLOOKUP(A37,Claim!C:C,Claim!J:J) -> 1 | J37: =_xlfn.XLOOKUP(A37,Claim!C:C,Claim!M:M) -> REQUEST_GARANSI | K37: =_xlfn.XLOOKUP(A37,Claim!C:C,Claim!O:O) -> Approved | L37: =_xlfn.XLOOKUP(A37,Claim!C:C,Claim!P:P) -> MSS Pending Form | M37: =_xlfn.XLOOKUP(A37,Claim!C:C,Claim!Q:Q) -> - | N37: {=_xlfn.IFS( OR(L37="Cancel", L37="Canceled", L37="Reject", L37="Rejected"), "Cancel / Rejected", AND(OR(J37="Request_Garansi", J37="Perbaikan_Asset"), OR(L37="Approved", L37="PMO Pending")), "MSS Need Send", TRUE, "Waiting Approval" )} -> Waiting Approval | O37: {=_xlfn.IFS( OR(M37="Cancel", M37="Canceled", M37="Reject", M37="Rejected", K37="Cancel", K37="Canceled", K37="Reject", K37="Rejected", L37="Cancel", L37="Canceled", L37="Reject", L37="Rejected"), "Cancel / Rejected", AND(OR(J37="Perbaikan_Asset"), OR(M37="KSO Pending")), "KSO Need Send", TRUE, "Waiting Approval" )} -> Waiting Approval | Q37: {=_xlfn.IFS( OR(M37="Cancel", M37="Canceled", M37="Reject", M37="Rejected", K37="Cancel", K37="Canceled", K37="Reject", K37="Rejected", L37="Cancel", L37="Canceled", L37="Reject", L37="Rejected"), "Cancel / Rejected", P37<>"", "MSS Done Send", N37="MSS Need Send", "MSS Need Send", TRUE, "Waiting Approval" )} -> Waiting Approval | S37: {=_xlfn.IFS( OR(M37="Cancel", M37="Canceled", M37="Reject", M37="Rejected", K37="Cancel", K37="Canceled", K37="Reject", K37="Rejected", L37="Cancel", L37="Canceled", L37="Reject", L37="Rejected"), "Cancel / Rejected", R37<>"", "KSO Done Send", Q37="MSS Need Send", "MSS Need Send", O37="KSO Need Send", "KSO Need Send", TRUE, "Waiting Approval" )} -> Waiting Approval
A38: PRE-APPROVAL-KLAIM-GARANSI/PMO/X/2026/0042 | B38: KLT00059 | C38: =_xlfn.XLOOKUP(B38,Engpar!A:A,Engpar!C:C) -> TUMBANG TAWAN | D38: =_xlfn.XLOOKUP(B38,Engpar!A:A,Engpar!F:F) -> KALIMANTAN TENGAH | E38: =_xlfn.XLOOKUP(B38,Engpar!A:A,Engpar!G:G) -> KOTAWARINGIN TIMUR | F38: =_xlfn.XLOOKUP(B38,Engpar!A:A,Engpar!J:J) -> -1.63002 | G38: =_xlfn.XLOOKUP(B38,Engpar!A:A,Engpar!K:K) -> 112.2789 | H38: =_xlfn.XLOOKUP(A38,Claim!C:C,Claim!I:I) -> SOLAR CHARGE CONTROLLER | I38: =_xlfn.XLOOKUP(A38,Claim!C:C,Claim!J:J) -> 1 | J38: =_xlfn.XLOOKUP(A38,Claim!C:C,Claim!M:M) -> PRE_APPROVAL | K38: =_xlfn.XLOOKUP(A38,Claim!C:C,Claim!O:O) -> KSO Pending | L38: =_xlfn.XLOOKUP(A38,Claim!C:C,Claim!P:P) -> - | M38: =_xlfn.XLOOKUP(A38,Claim!C:C,Claim!Q:Q) -> - | N38: {=_xlfn.IFS( OR(L38="Cancel", L38="Canceled", L38="Reject", L38="Rejected"), "Cancel / Rejected", AND(OR(J38="Request_Garansi", J38="Perbaikan_Asset"), OR(L38="Approved", L38="PMO Pending")), "MSS Need Send", TRUE, "Waiting Approval" )} -> Waiting Approval | O38: {=_xlfn.IFS( OR(M38="Cancel", M38="Canceled", M38="Reject", M38="Rejected", K38="Cancel", K38="Canceled", K38="Reject", K38="Rejected", L38="Cancel", L38="Canceled", L38="Reject", L38="Rejected"), "Cancel / Rejected", AND(OR(J38="Perbaikan_Asset"), OR(M38="KSO Pending")), "KSO Need Send", TRUE, "Waiting Approval" )} -> Waiting Approval | P38: 21/08/2026 | Q38: {=_xlfn.IFS( OR(M38="Cancel", M38="Canceled", M38="Reject", M38="Rejected", K38="Cancel", K38="Canceled", K38="Reject", K38="Rejected", L38="Cancel", L38="Canceled", L38="Reject", L38="Rejected"), "Cancel / Rejected", P38<>"", "MSS Done Send", N38="MSS Need Send", "MSS Need Send", TRUE, "Waiting Approval" )} -> MSS Done Send | S38: {=_xlfn.IFS( OR(M38="Cancel", M38="Canceled", M38="Reject", M38="Rejected", K38="Cancel", K38="Canceled", K38="Reject", K38="Rejected", L38="Cancel", L38="Canceled", L38="Reject", L38="Rejected"), "Cancel / Rejected", R38<>"", "KSO Done Send", Q38="MSS Need Send", "MSS Need Send", O38="KSO Need Send", "KSO Need Send", TRUE, "Waiting Approval" )} -> Waiting Approval
A39: PRE-APPROVAL-KLAIM-GARANSI/PMO/X/2026/0041 | B39: KLI00039 | C39: =_xlfn.XLOOKUP(B39,Engpar!A:A,Engpar!C:C) -> TELUK SUMBANG | D39: =_xlfn.XLOOKUP(B39,Engpar!A:A,Engpar!F:F) -> KALIMANTAN TIMUR | E39: =_xlfn.XLOOKUP(B39,Engpar!A:A,Engpar!G:G) -> BERAU | F39: =_xlfn.XLOOKUP(B39,Engpar!A:A,Engpar!J:J) -> 1.05237 | G39: =_xlfn.XLOOKUP(B39,Engpar!A:A,Engpar!K:K) -> 118.83427 | H39: =_xlfn.XLOOKUP(A39,Claim!C:C,Claim!I:I) -> INVERTER 300 W | I39: =_xlfn.XLOOKUP(A39,Claim!C:C,Claim!J:J) -> 1 | J39: =_xlfn.XLOOKUP(A39,Claim!C:C,Claim!M:M) -> PRE_APPROVAL | K39: =_xlfn.XLOOKUP(A39,Claim!C:C,Claim!O:O) -> KSO Pending | L39: =_xlfn.XLOOKUP(A39,Claim!C:C,Claim!P:P) -> - | M39: =_xlfn.XLOOKUP(A39,Claim!C:C,Claim!Q:Q) -> - | N39: {=_xlfn.IFS( OR(L39="Cancel", L39="Canceled", L39="Reject", L39="Rejected"), "Cancel / Rejected", AND(OR(J39="Request_Garansi", J39="Perbaikan_Asset"), OR(L39="Approved", L39="PMO Pending")), "MSS Need Send", TRUE, "Waiting Approval" )} -> Waiting Approval | O39: {=_xlfn.IFS( OR(M39="Cancel", M39="Canceled", M39="Reject", M39="Rejected", K39="Cancel", K39="Canceled", K39="Reject", K39="Rejected", L39="Cancel", L39="Canceled", L39="Reject", L39="Rejected"), "Cancel / Rejected", AND(OR(J39="Perbaikan_Asset"), OR(M39="KSO Pending")), "KSO Need Send", TRUE, "Waiting Approval" )} -> Waiting Approval | P39: 25/09/2026 | Q39: {=_xlfn.IFS( OR(M39="Cancel", M39="Canceled", M39="Reject", M39="Rejected", K39="Cancel", K39="Canceled", K39="Reject", K39="Rejected", L39="Cancel", L39="Canceled", L39="Reject", L39="Rejected"), "Cancel / Rejected", P39<>"", "MSS Done Send", N39="MSS Need Send", "MSS Need Send", TRUE, "Waiting Approval" )} -> MSS Done Send | S39: {=_xlfn.IFS( OR(M39="Cancel", M39="Canceled", M39="Reject", M39="Rejected", K39="Cancel", K39="Canceled", K39="Reject", K39="Rejected", L39="Cancel", L39="Canceled", L39="Reject", L39="Rejected"), "Cancel / Rejected", R39<>"", "KSO Done Send", Q39="MSS Need Send", "MSS Need Send", O39="KSO Need Send", "KSO Need Send", TRUE, "Waiting Approval" )} -> Waiting Approval
A40: PRE-APPROVAL-KLAIM-GARANSI/PMO/X/2026/0040 | B40: KLT005 | C40: =_xlfn.XLOOKUP(B40,Engpar!A:A,Engpar!C:C) -> TUMBANG BAI | D40: =_xlfn.XLOOKUP(B40,Engpar!A:A,Engpar!F:F) -> KALIMANTAN TENGAH | E40: =_xlfn.XLOOKUP(B40,Engpar!A:A,Engpar!G:G) -> SERUYAN | F40: =_xlfn.XLOOKUP(B40,Engpar!A:A,Engpar!J:J) -> -1.95525 | G40: =_xlfn.XLOOKUP(B40,Engpar!A:A,Engpar!K:K) -> 112.16068 | H40: =_xlfn.XLOOKUP(A40,Claim!C:C,Claim!I:I) -> SOLAR CHARGE CONTROLLER | I40: =_xlfn.XLOOKUP(A40,Claim!C:C,Claim!J:J) -> 1 | J40: =_xlfn.XLOOKUP(A40,Claim!C:C,Claim!M:M) -> REQUEST_GARANSI | K40: =_xlfn.XLOOKUP(A40,Claim!C:C,Claim!O:O) -> Approved | L40: =_xlfn.XLOOKUP(A40,Claim!C:C,Claim!P:P) -> MSS Pending Form | M40: =_xlfn.XLOOKUP(A40,Claim!C:C,Claim!Q:Q) -> - | N40: {=_xlfn.IFS( OR(L40="Cancel", L40="Canceled", L40="Reject", L40="Rejected"), "Cancel / Rejected", AND(OR(J40="Request_Garansi", J40="Perbaikan_Asset"), OR(L40="Approved", L40="PMO Pending")), "MSS Need Send", TRUE, "Waiting Approval" )} -> Waiting Approval | O40: {=_xlfn.IFS( OR(M40="Cancel", M40="Canceled", M40="Reject", M40="Rejected", K40="Cancel", K40="Canceled", K40="Reject", K40="Rejected", L40="Cancel", L40="Canceled", L40="Reject", L40="Rejected"), "Cancel / Rejected", AND(OR(J40="Perbaikan_Asset"), OR(M40="KSO Pending")), "KSO Need Send", TRUE, "Waiting Approval" )} -> Waiting Approval | Q40: {=_xlfn.IFS( OR(M40="Cancel", M40="Canceled", M40="Reject", M40="Rejected", K40="Cancel", K40="Canceled", K40="Reject", K40="Rejected", L40="Cancel", L40="Canceled", L40="Reject", L40="Rejected"), "Cancel / Rejected", P40<>"", "MSS Done Send", N40="MSS Need Send", "MSS Need Send", TRUE, "Waiting Approval" )} -> Waiting Approval | S40: {=_xlfn.IFS( OR(M40="Cancel", M40="Canceled", M40="Reject", M40="Rejected", K40="Cancel", K40="Canceled", K40="Reject", K40="Rejected", L40="Cancel", L40="Canceled", L40="Reject", L40="Rejected"), "Cancel / Rejected", R40<>"", "KSO Done Send", Q40="MSS Need Send", "MSS Need Send", O40="KSO Need Send", "KSO Need Send", TRUE, "Waiting Approval" )} -> Waiting Approval
A41: PRE-APPROVAL-KLAIM-GARANSI/PMO/X/2026/0039 | B41: KLT0018 | C41: =_xlfn.XLOOKUP(B41,Engpar!A:A,Engpar!C:C) -> TUMBANG SUEI | D41: =_xlfn.XLOOKUP(B41,Engpar!A:A,Engpar!F:F) -> KALIMANTAN TENGAH | E41: =_xlfn.XLOOKUP(B41,Engpar!A:A,Engpar!G:G) -> SERUYAN | F41: =_xlfn.XLOOKUP(B41,Engpar!A:A,Engpar!J:J) -> -1.31559 | G41: =_xlfn.XLOOKUP(B41,Engpar!A:A,Engpar!K:K) -> 111.855 | H41: =_xlfn.XLOOKUP(A41,Claim!C:C,Claim!I:I) -> BATERAI | I41: =_xlfn.XLOOKUP(A41,Claim!C:C,Claim!J:J) -> 2 | J41: =_xlfn.XLOOKUP(A41,Claim!C:C,Claim!M:M) -> PRE_APPROVAL | K41: =_xlfn.XLOOKUP(A41,Claim!C:C,Claim!O:O) -> Canceled | L41: =_xlfn.XLOOKUP(A41,Claim!C:C,Claim!P:P) -> - | M41: =_xlfn.XLOOKUP(A41,Claim!C:C,Claim!Q:Q) -> - | N41: {=_xlfn.IFS( OR(L41="Cancel", L41="Canceled", L41="Reject", L41="Rejected"), "Cancel / Rejected", AND(OR(J41="Request_Garansi", J41="Perbaikan_Asset"), OR(L41="Approved", L41="PMO Pending")), "MSS Need Send", TRUE, "Waiting Approval" )} -> Waiting Approval | O41: {=_xlfn.IFS( OR(M41="Cancel", M41="Canceled", M41="Reject", M41="Rejected", K41="Cancel", K41="Canceled", K41="Reject", K41="Rejected", L41="Cancel", L41="Canceled", L41="Reject", L41="Rejected"), "Cancel / Rejected", AND(OR(J41="Perbaikan_Asset"), OR(M41="KSO Pending")), "KSO Need Send", TRUE, "Waiting Approval" )} -> Cancel / Rejected | Q41: {=_xlfn.IFS( OR(M41="Cancel", M41="Canceled", M41="Reject", M41="Rejected", K41="Cancel", K41="Canceled", K41="Reject", K41="Rejected", L41="Cancel", L41="Canceled", L41="Reject", L41="Rejected"), "Cancel / Rejected", P41<>"", "MSS Done Send", N41="MSS Need Send", "MSS Need Send", TRUE, "Waiting Approval" )} -> Cancel / Rejected | S41: {=_xlfn.IFS( OR(M41="Cancel", M41="Canceled", M41="Reject", M41="Rejected", K41="Cancel", K41="Canceled", K41="Reject", K41="Rejected", L41="Cancel", L41="Canceled", L41="Reject", L41="Rejected"), "Cancel / Rejected", R41<>"", "KSO Done Send", Q41="MSS Need Send", "MSS Need Send", O41="KSO Need Send", "KSO Need Send", TRUE, "Waiting Approval" )} -> Cancel / Rejected
A42: PRE-APPROVAL-KLAIM-GARANSI/PMO/X/2026/0035 | B42: KLT00042 | C42: =_xlfn.XLOOKUP(B42,Engpar!A:A,Engpar!C:C) -> RANTAU BAHAI | D42: =_xlfn.XLOOKUP(B42,Engpar!A:A,Engpar!F:F) -> KALIMANTAN TENGAH | E42: =_xlfn.XLOOKUP(B42,Engpar!A:A,Engpar!G:G) -> KATINGAN | F42: =_xlfn.XLOOKUP(B42,Engpar!A:A,Engpar!J:J) -> -1.05784 | G42: =_xlfn.XLOOKUP(B42,Engpar!A:A,Engpar!K:K) -> 112.43424 | H42: =_xlfn.XLOOKUP(A42,Claim!C:C,Claim!I:I) -> BATERAI | I42: =_xlfn.XLOOKUP(A42,Claim!C:C,Claim!J:J) -> 2 | J42: =_xlfn.XLOOKUP(A42,Claim!C:C,Claim!M:M) -> REQUEST_GARANSI | K42: =_xlfn.XLOOKUP(A42,Claim!C:C,Claim!O:O) -> Approved | L42: =_xlfn.XLOOKUP(A42,Claim!C:C,Claim!P:P) -> MSS Pending Form | M42: =_xlfn.XLOOKUP(A42,Claim!C:C,Claim!Q:Q) -> - | N42: {=_xlfn.IFS( OR(L42="Cancel", L42="Canceled", L42="Reject", L42="Rejected"), "Cancel / Rejected", AND(OR(J42="Request_Garansi", J42="Perbaikan_Asset"), OR(L42="Approved", L42="PMO Pending")), "MSS Need Send", TRUE, "Waiting Approval" )} -> Waiting Approval | O42: {=_xlfn.IFS( OR(M42="Cancel", M42="Canceled", M42="Reject", M42="Rejected", K42="Cancel", K42="Canceled", K42="Reject", K42="Rejected", L42="Cancel", L42="Canceled", L42="Reject", L42="Rejected"), "Cancel / Rejected", AND(OR(J42="Perbaikan_Asset"), OR(M42="KSO Pending")), "KSO Need Send", TRUE, "Waiting Approval" )} -> Waiting Approval | P42: 21/08/2026 | Q42: {=_xlfn.IFS( OR(M42="Cancel", M42="Canceled", M42="Reject", M42="Rejected", K42="Cancel", K42="Canceled", K42="Reject", K42="Rejected", L42="Cancel", L42="Canceled", L42="Reject", L42="Rejected"), "Cancel / Rejected", P42<>"", "MSS Done Send", N42="MSS Need Send", "MSS Need Send", TRUE, "Waiting Approval" )} -> MSS Done Send | S42: {=_xlfn.IFS( OR(M42="Cancel", M42="Canceled", M42="Reject", M42="Rejected", K42="Cancel", K42="Canceled", K42="Reject", K42="Rejected", L42="Cancel", L42="Canceled", L42="Reject", L42="Rejected"), "Cancel / Rejected", R42<>"", "KSO Done Send", Q42="MSS Need Send", "MSS Need Send", O42="KSO Need Send", "KSO Need Send", TRUE, "Waiting Approval" )} -> Waiting Approval
A43: PRE-APPROVAL-KLAIM-GARANSI/PMO/X/2026/0034 | B43: KLI00043 | C43: =_xlfn.XLOOKUP(B43,Engpar!A:A,Engpar!C:C) -> TANJUNG MANGKALIHAT | D43: =_xlfn.XLOOKUP(B43,Engpar!A:A,Engpar!F:F) -> KALIMANTAN TIMUR | E43: =_xlfn.XLOOKUP(B43,Engpar!A:A,Engpar!G:G) -> KUTAI TIMUR | F43: =_xlfn.XLOOKUP(B43,Engpar!A:A,Engpar!J:J) -> 1.0035 | G43: =_xlfn.XLOOKUP(B43,Engpar!A:A,Engpar!K:K) -> 118.97835 | H43: =_xlfn.XLOOKUP(A43,Claim!C:C,Claim!I:I) -> INVERTER 300 W | I43: =_xlfn.XLOOKUP(A43,Claim!C:C,Claim!J:J) -> 1 | J43: =_xlfn.XLOOKUP(A43,Claim!C:C,Claim!M:M) -> REQUEST_GARANSI | K43: =_xlfn.XLOOKUP(A43,Claim!C:C,Claim!O:O) -> Approved | L43: =_xlfn.XLOOKUP(A43,Claim!C:C,Claim!P:P) -> MSS Pending Form | M43: =_xlfn.XLOOKUP(A43,Claim!C:C,Claim!Q:Q) -> - | N43: {=_xlfn.IFS( OR(L43="Cancel", L43="Canceled", L43="Reject", L43="Rejected"), "Cancel / Rejected", AND(OR(J43="Request_Garansi", J43="Perbaikan_Asset"), OR(L43="Approved", L43="PMO Pending")), "MSS Need Send", TRUE, "Waiting Approval" )} -> Waiting Approval | O43: {=_xlfn.IFS( OR(M43="Cancel", M43="Canceled", M43="Reject", M43="Rejected", K43="Cancel", K43="Canceled", K43="Reject", K43="Rejected", L43="Cancel", L43="Canceled", L43="Reject", L43="Rejected"), "Cancel / Rejected", AND(OR(J43="Perbaikan_Asset"), OR(M43="KSO Pending")), "KSO Need Send", TRUE, "Waiting Approval" )} -> Waiting Approval | P43: 25/09/2026 | Q43: {=_xlfn.IFS( OR(M43="Cancel", M43="Canceled", M43="Reject", M43="Rejected", K43="Cancel", K43="Canceled", K43="Reject", K43="Rejected", L43="Cancel", L43="Canceled", L43="Reject", L43="Rejected"), "Cancel / Rejected", P43<>"", "MSS Done Send", N43="MSS Need Send", "MSS Need Send", TRUE, "Waiting Approval" )} -> MSS Done Send | S43: {=_xlfn.IFS( OR(M43="Cancel", M43="Canceled", M43="Reject", M43="Rejected", K43="Cancel", K43="Canceled", K43="Reject", K43="Rejected", L43="Cancel", L43="Canceled", L43="Reject", L43="Rejected"), "Cancel / Rejected", R43<>"", "KSO Done Send", Q43="MSS Need Send", "MSS Need Send", O43="KSO Need Send", "KSO Need Send", TRUE, "Waiting Approval" )} -> Waiting Approval
A44: PRE-APPROVAL-KLAIM-GARANSI/PMO/X/2026/0033 | B44: KLI00044 | C44: =_xlfn.XLOOKUP(B44,Engpar!A:A,Engpar!C:C) -> SANDARAN | D44: =_xlfn.XLOOKUP(B44,Engpar!A:A,Engpar!F:F) -> KALIMANTAN TIMUR | E44: =_xlfn.XLOOKUP(B44,Engpar!A:A,Engpar!G:G) -> KUTAI TIMUR | F44: =_xlfn.XLOOKUP(B44,Engpar!A:A,Engpar!J:J) -> 0.87952 | G44: =_xlfn.XLOOKUP(B44,Engpar!A:A,Engpar!K:K) -> 118.87077 | H44: =_xlfn.XLOOKUP(A44,Claim!C:C,Claim!I:I) -> SOLAR CHARGE CONTROLLER | I44: =_xlfn.XLOOKUP(A44,Claim!C:C,Claim!J:J) -> 1 | J44: =_xlfn.XLOOKUP(A44,Claim!C:C,Claim!M:M) -> PRE_APPROVAL | K44: =_xlfn.XLOOKUP(A44,Claim!C:C,Claim!O:O) -> Rejected | L44: =_xlfn.XLOOKUP(A44,Claim!C:C,Claim!P:P) -> - | M44: =_xlfn.XLOOKUP(A44,Claim!C:C,Claim!Q:Q) -> - | N44: {=_xlfn.IFS( OR(L44="Cancel", L44="Canceled", L44="Reject", L44="Rejected"), "Cancel / Rejected", AND(OR(J44="Request_Garansi", J44="Perbaikan_Asset"), OR(L44="Approved", L44="PMO Pending")), "MSS Need Send", TRUE, "Waiting Approval" )} -> Waiting Approval | O44: {=_xlfn.IFS( OR(M44="Cancel", M44="Canceled", M44="Reject", M44="Rejected", K44="Cancel", K44="Canceled", K44="Reject", K44="Rejected", L44="Cancel", L44="Canceled", L44="Reject", L44="Rejected"), "Cancel / Rejected", AND(OR(J44="Perbaikan_Asset"), OR(M44="KSO Pending")), "KSO Need Send", TRUE, "Waiting Approval" )} -> Cancel / Rejected | Q44: {=_xlfn.IFS( OR(M44="Cancel", M44="Canceled", M44="Reject", M44="Rejected", K44="Cancel", K44="Canceled", K44="Reject", K44="Rejected", L44="Cancel", L44="Canceled", L44="Reject", L44="Rejected"), "Cancel / Rejected", P44<>"", "MSS Done Send", N44="MSS Need Send", "MSS Need Send", TRUE, "Waiting Approval" )} -> Cancel / Rejected | S44: {=_xlfn.IFS( OR(M44="Cancel", M44="Canceled", M44="Reject", M44="Rejected", K44="Cancel", K44="Canceled", K44="Reject", K44="Rejected", L44="Cancel", L44="Canceled", L44="Reject", L44="Rejected"), "Cancel / Rejected", R44<>"", "KSO Done Send", Q44="MSS Need Send", "MSS Need Send", O44="KSO Need Send", "KSO Need Send", TRUE, "Waiting Approval" )} -> Cancel / Rejected
A45: PRE-APPROVAL-KLAIM-GARANSI/PMO/X/2026/0032 | B45: KLT00042 | C45: =_xlfn.XLOOKUP(B45,Engpar!A:A,Engpar!C:C) -> RANTAU BAHAI | D45: =_xlfn.XLOOKUP(B45,Engpar!A:A,Engpar!F:F) -> KALIMANTAN TENGAH | E45: =_xlfn.XLOOKUP(B45,Engpar!A:A,Engpar!G:G) -> KATINGAN | F45: =_xlfn.XLOOKUP(B45,Engpar!A:A,Engpar!J:J) -> -1.05784 | G45: =_xlfn.XLOOKUP(B45,Engpar!A:A,Engpar!K:K) -> 112.43424 | H45: =_xlfn.XLOOKUP(A45,Claim!C:C,Claim!I:I) -> BATERAI | I45: =_xlfn.XLOOKUP(A45,Claim!C:C,Claim!J:J) -> 2 | J45: =_xlfn.XLOOKUP(A45,Claim!C:C,Claim!M:M) -> PRE_APPROVAL | K45: =_xlfn.XLOOKUP(A45,Claim!C:C,Claim!O:O) -> Rejected | L45: =_xlfn.XLOOKUP(A45,Claim!C:C,Claim!P:P) -> - | M45: =_xlfn.XLOOKUP(A45,Claim!C:C,Claim!Q:Q) -> - | N45: {=_xlfn.IFS( OR(L45="Cancel", L45="Canceled", L45="Reject", L45="Rejected"), "Cancel / Rejected", AND(OR(J45="Request_Garansi", J45="Perbaikan_Asset"), OR(L45="Approved", L45="PMO Pending")), "MSS Need Send", TRUE, "Waiting Approval" )} -> Waiting Approval | O45: {=_xlfn.IFS( OR(M45="Cancel", M45="Canceled", M45="Reject", M45="Rejected", K45="Cancel", K45="Canceled", K45="Reject", K45="Rejected", L45="Cancel", L45="Canceled", L45="Reject", L45="Rejected"), "Cancel / Rejected", AND(OR(J45="Perbaikan_Asset"), OR(M45="KSO Pending")), "KSO Need Send", TRUE, "Waiting Approval" )} -> Cancel / Rejected | P45: 17/09/2026 | Q45: {=_xlfn.IFS( OR(M45="Cancel", M45="Canceled", M45="Reject", M45="Rejected", K45="Cancel", K45="Canceled", K45="Reject", K45="Rejected", L45="Cancel", L45="Canceled", L45="Reject", L45="Rejected"), "Cancel / Rejected", P45<>"", "MSS Done Send", N45="MSS Need Send", "MSS Need Send", TRUE, "Waiting Approval" )} -> Cancel / Rejected | S45: {=_xlfn.IFS( OR(M45="Cancel", M45="Canceled", M45="Reject", M45="Rejected", K45="Cancel", K45="Canceled", K45="Reject", K45="Rejected", L45="Cancel", L45="Canceled", L45="Reject", L45="Rejected"), "Cancel / Rejected", R45<>"", "KSO Done Send", Q45="MSS Need Send", "MSS Need Send", O45="KSO Need Send", "KSO Need Send", TRUE, "Waiting Approval" )} -> Cancel / Rejected
A46: PRE-APPROVAL-KLAIM-GARANSI/PMO/X/2026/0031 | B46: KLI00043 | C46: =_xlfn.XLOOKUP(B46,Engpar!A:A,Engpar!C:C) -> TANJUNG MANGKALIHAT | D46: =_xlfn.XLOOKUP(B46,Engpar!A:A,Engpar!F:F) -> KALIMANTAN TIMUR | E46: =_xlfn.XLOOKUP(B46,Engpar!A:A,Engpar!G:G) -> KUTAI TIMUR | F46: =_xlfn.XLOOKUP(B46,Engpar!A:A,Engpar!J:J) -> 1.0035 | G46: =_xlfn.XLOOKUP(B46,Engpar!A:A,Engpar!K:K) -> 118.97835 | H46: =_xlfn.XLOOKUP(A46,Claim!C:C,Claim!I:I) -> SOLAR CHARGE CONTROLLER | I46: =_xlfn.XLOOKUP(A46,Claim!C:C,Claim!J:J) -> 1 | J46: =_xlfn.XLOOKUP(A46,Claim!C:C,Claim!M:M) -> REQUEST_GARANSI | K46: =_xlfn.XLOOKUP(A46,Claim!C:C,Claim!O:O) -> Approved | L46: =_xlfn.XLOOKUP(A46,Claim!C:C,Claim!P:P) -> MSS Pending Form | M46: =_xlfn.XLOOKUP(A46,Claim!C:C,Claim!Q:Q) -> - | N46: {=_xlfn.IFS( OR(L46="Cancel", L46="Canceled", L46="Reject", L46="Rejected"), "Cancel / Rejected", AND(OR(J46="Request_Garansi", J46="Perbaikan_Asset"), OR(L46="Approved", L46="PMO Pending")), "MSS Need Send", TRUE, "Waiting Approval" )} -> Waiting Approval | O46: {=_xlfn.IFS( OR(M46="Cancel", M46="Canceled", M46="Reject", M46="Rejected", K46="Cancel", K46="Canceled", K46="Reject", K46="Rejected", L46="Cancel", L46="Canceled", L46="Reject", L46="Rejected"), "Cancel / Rejected", AND(OR(J46="Perbaikan_Asset"), OR(M46="KSO Pending")), "KSO Need Send", TRUE, "Waiting Approval" )} -> Waiting Approval | Q46: {=_xlfn.IFS( OR(M46="Cancel", M46="Canceled", M46="Reject", M46="Rejected", K46="Cancel", K46="Canceled", K46="Reject", K46="Rejected", L46="Cancel", L46="Canceled", L46="Reject", L46="Rejected"), "Cancel / Rejected", P46<>"", "MSS Done Send", N46="MSS Need Send", "MSS Need Send", TRUE, "Waiting Approval" )} -> Waiting Approval | S46: {=_xlfn.IFS( OR(M46="Cancel", M46="Canceled", M46="Reject", M46="Rejected", K46="Cancel", K46="Canceled", K46="Reject", K46="Rejected", L46="Cancel", L46="Canceled", L46="Reject", L46="Rejected"), "Cancel / Rejected", R46<>"", "KSO Done Send", Q46="MSS Need Send", "MSS Need Send", O46="KSO Need Send", "KSO Need Send", TRUE, "Waiting Approval" )} -> Waiting Approval
A47: PRE-APPROVAL-KLAIM-GARANSI/PMO/X/2026/0030 | B47: KLT00061 | C47: =_xlfn.XLOOKUP(B47,Engpar!A:A,Engpar!C:C) -> TUMBANG SALUANG | D47: =_xlfn.XLOOKUP(B47,Engpar!A:A,Engpar!F:F) -> KALIMANTAN TENGAH | E47: =_xlfn.XLOOKUP(B47,Engpar!A:A,Engpar!G:G) -> KOTAWARINGIN TIMUR | F47: =_xlfn.XLOOKUP(B47,Engpar!A:A,Engpar!J:J) -> -1.5667 | G47: =_xlfn.XLOOKUP(B47,Engpar!A:A,Engpar!K:K) -> 112.2635 | H47: =_xlfn.XLOOKUP(A47,Claim!C:C,Claim!I:I) -> INVERTER 300 W | I47: =_xlfn.XLOOKUP(A47,Claim!C:C,Claim!J:J) -> 1 | J47: =_xlfn.XLOOKUP(A47,Claim!C:C,Claim!M:M) -> REQUEST_GARANSI | K47: =_xlfn.XLOOKUP(A47,Claim!C:C,Claim!O:O) -> Approved | L47: =_xlfn.XLOOKUP(A47,Claim!C:C,Claim!P:P) -> MSS Pending Form | M47: =_xlfn.XLOOKUP(A47,Claim!C:C,Claim!Q:Q) -> - | N47: {=_xlfn.IFS( OR(L47="Cancel", L47="Canceled", L47="Reject", L47="Rejected"), "Cancel / Rejected", AND(OR(J47="Request_Garansi", J47="Perbaikan_Asset"), OR(L47="Approved", L47="PMO Pending")), "MSS Need Send", TRUE, "Waiting Approval" )} -> Waiting Approval | O47: {=_xlfn.IFS( OR(M47="Cancel", M47="Canceled", M47="Reject", M47="Rejected", K47="Cancel", K47="Canceled", K47="Reject", K47="Rejected", L47="Cancel", L47="Canceled", L47="Reject", L47="Rejected"), "Cancel / Rejected", AND(OR(J47="Perbaikan_Asset"), OR(M47="KSO Pending")), "KSO Need Send", TRUE, "Waiting Approval" )} -> Waiting Approval | P47: 25/09/2026 | Q47: {=_xlfn.IFS( OR(M47="Cancel", M47="Canceled", M47="Reject", M47="Rejected", K47="Cancel", K47="Canceled", K47="Reject", K47="Rejected", L47="Cancel", L47="Canceled", L47="Reject", L47="Rejected"), "Cancel / Rejected", P47<>"", "MSS Done Send", N47="MSS Need Send", "MSS Need Send", TRUE, "Waiting Approval" )} -> MSS Done Send | S47: {=_xlfn.IFS( OR(M47="Cancel", M47="Canceled", M47="Reject", M47="Rejected", K47="Cancel", K47="Canceled", K47="Reject", K47="Rejected", L47="Cancel", L47="Canceled", L47="Reject", L47="Rejected"), "Cancel / Rejected", R47<>"", "KSO Done Send", Q47="MSS Need Send", "MSS Need Send", O47="KSO Need Send", "KSO Need Send", TRUE, "Waiting Approval" )} -> Waiting Approval
A48: PRE-APPROVAL-KLAIM-GARANSI/PMO/X/2026/0029 | B48: KLI00039 | C48: =_xlfn.XLOOKUP(B48,Engpar!A:A,Engpar!C:C) -> TELUK SUMBANG | D48: =_xlfn.XLOOKUP(B48,Engpar!A:A,Engpar!F:F) -> KALIMANTAN TIMUR | E48: =_xlfn.XLOOKUP(B48,Engpar!A:A,Engpar!G:G) -> BERAU | F48: =_xlfn.XLOOKUP(B48,Engpar!A:A,Engpar!J:J) -> 1.05237 | G48: =_xlfn.XLOOKUP(B48,Engpar!A:A,Engpar!K:K) -> 118.83427 | H48: =_xlfn.XLOOKUP(A48,Claim!C:C,Claim!I:I) -> YARD LAMP | I48: =_xlfn.XLOOKUP(A48,Claim!C:C,Claim!J:J) -> 1 | J48: =_xlfn.XLOOKUP(A48,Claim!C:C,Claim!M:M) -> PRE_APPROVAL | K48: =_xlfn.XLOOKUP(A48,Claim!C:C,Claim!O:O) -> Rejected | L48: =_xlfn.XLOOKUP(A48,Claim!C:C,Claim!P:P) -> - | M48: =_xlfn.XLOOKUP(A48,Claim!C:C,Claim!Q:Q) -> - | N48: {=_xlfn.IFS( OR(L48="Cancel", L48="Canceled", L48="Reject", L48="Rejected"), "Cancel / Rejected", AND(OR(J48="Request_Garansi", J48="Perbaikan_Asset"), OR(L48="Approved", L48="PMO Pending")), "MSS Need Send", TRUE, "Waiting Approval" )} -> Waiting Approval | O48: {=_xlfn.IFS( OR(M48="Cancel", M48="Canceled", M48="Reject", M48="Rejected", K48="Cancel", K48="Canceled", K48="Reject", K48="Rejected", L48="Cancel", L48="Canceled", L48="Reject", L48="Rejected"), "Cancel / Rejected", AND(OR(J48="Perbaikan_Asset"), OR(M48="KSO Pending")), "KSO Need Send", TRUE, "Waiting Approval" )} -> Cancel / Rejected | Q48: {=_xlfn.IFS( OR(M48="Cancel", M48="Canceled", M48="Reject", M48="Rejected", K48="Cancel", K48="Canceled", K48="Reject", K48="Rejected", L48="Cancel", L48="Canceled", L48="Reject", L48="Rejected"), "Cancel / Rejected", P48<>"", "MSS Done Send", N48="MSS Need Send", "MSS Need Send", TRUE, "Waiting Approval" )} -> Cancel / Rejected | S48: {=_xlfn.IFS( OR(M48="Cancel", M48="Canceled", M48="Reject", M48="Rejected", K48="Cancel", K48="Canceled", K48="Reject", K48="Rejected", L48="Cancel", L48="Canceled", L48="Reject", L48="Rejected"), "Cancel / Rejected", R48<>"", "KSO Done Send", Q48="MSS Need Send", "MSS Need Send", O48="KSO Need Send", "KSO Need Send", TRUE, "Waiting Approval" )} -> Cancel / Rejected
A49: PRE-APPROVAL-KLAIM-GARANSI/PMO/X/2026/0028 | B49: KLT00061 | C49: =_xlfn.XLOOKUP(B49,Engpar!A:A,Engpar!C:C) -> TUMBANG SALUANG | D49: =_xlfn.XLOOKUP(B49,Engpar!A:A,Engpar!F:F) -> KALIMANTAN TENGAH | E49: =_xlfn.XLOOKUP(B49,Engpar!A:A,Engpar!G:G) -> KOTAWARINGIN TIMUR | F49: =_xlfn.XLOOKUP(B49,Engpar!A:A,Engpar!J:J) -> -1.5667 | G49: =_xlfn.XLOOKUP(B49,Engpar!A:A,Engpar!K:K) -> 112.2635 | H49: =_xlfn.XLOOKUP(A49,Claim!C:C,Claim!I:I) -> BATERAI | I49: =_xlfn.XLOOKUP(A49,Claim!C:C,Claim!J:J) -> 2 | J49: =_xlfn.XLOOKUP(A49,Claim!C:C,Claim!M:M) -> REQUEST_GARANSI | K49: =_xlfn.XLOOKUP(A49,Claim!C:C,Claim!O:O) -> Approved | L49: =_xlfn.XLOOKUP(A49,Claim!C:C,Claim!P:P) -> MSS Pending Form | M49: =_xlfn.XLOOKUP(A49,Claim!C:C,Claim!Q:Q) -> - | N49: {=_xlfn.IFS( OR(L49="Cancel", L49="Canceled", L49="Reject", L49="Rejected"), "Cancel / Rejected", AND(OR(J49="Request_Garansi", J49="Perbaikan_Asset"), OR(L49="Approved", L49="PMO Pending")), "MSS Need Send", TRUE, "Waiting Approval" )} -> Waiting Approval | O49: {=_xlfn.IFS( OR(M49="Cancel", M49="Canceled", M49="Reject", M49="Rejected", K49="Cancel", K49="Canceled", K49="Reject", K49="Rejected", L49="Cancel", L49="Canceled", L49="Reject", L49="Rejected"), "Cancel / Rejected", AND(OR(J49="Perbaikan_Asset"), OR(M49="KSO Pending")), "KSO Need Send", TRUE, "Waiting Approval" )} -> Waiting Approval | Q49: {=_xlfn.IFS( OR(M49="Cancel", M49="Canceled", M49="Reject", M49="Rejected", K49="Cancel", K49="Canceled", K49="Reject", K49="Rejected", L49="Cancel", L49="Canceled", L49="Reject", L49="Rejected"), "Cancel / Rejected", P49<>"", "MSS Done Send", N49="MSS Need Send", "MSS Need Send", TRUE, "Waiting Approval" )} -> Waiting Approval | S49: {=_xlfn.IFS( OR(M49="Cancel", M49="Canceled", M49="Reject", M49="Rejected", K49="Cancel", K49="Canceled", K49="Reject", K49="Rejected", L49="Cancel", L49="Canceled", L49="Reject", L49="Rejected"), "Cancel / Rejected", R49<>"", "KSO Done Send", Q49="MSS Need Send", "MSS Need Send", O49="KSO Need Send", "KSO Need Send", TRUE, "Waiting Approval" )} -> Waiting Approval
A50: PRE-APPROVAL-KLAIM-GARANSI/PMO/X/2026/0027 | B50: KLT0023 | C50: =_xlfn.XLOOKUP(B50,Engpar!A:A,Engpar!C:C) -> TUMBANG SETOLI | D50: =_xlfn.XLOOKUP(B50,Engpar!A:A,Engpar!F:F) -> KALIMANTAN TENGAH | E50: =_xlfn.XLOOKUP(B50,Engpar!A:A,Engpar!G:G) -> SERUYAN | F50: =_xlfn.XLOOKUP(B50,Engpar!A:A,Engpar!J:J) -> -1.27744 | G50: =_xlfn.XLOOKUP(B50,Engpar!A:A,Engpar!K:K) -> 111.67767 | H50: =_xlfn.XLOOKUP(A50,Claim!C:C,Claim!I:I) -> BATERAI | I50: =_xlfn.XLOOKUP(A50,Claim!C:C,Claim!J:J) -> 1 | J50: =_xlfn.XLOOKUP(A50,Claim!C:C,Claim!M:M) -> REQUEST_GARANSI | K50: =_xlfn.XLOOKUP(A50,Claim!C:C,Claim!O:O) -> Approved | L50: =_xlfn.XLOOKUP(A50,Claim!C:C,Claim!P:P) -> MSS Pending Form | M50: =_xlfn.XLOOKUP(A50,Claim!C:C,Claim!Q:Q) -> - | N50: {=_xlfn.IFS( OR(L50="Cancel", L50="Canceled", L50="Reject", L50="Rejected"), "Cancel / Rejected", AND(OR(J50="Request_Garansi", J50="Perbaikan_Asset"), OR(L50="Approved", L50="PMO Pending")), "MSS Need Send", TRUE, "Waiting Approval" )} -> Waiting Approval | O50: {=_xlfn.IFS( OR(M50="Cancel", M50="Canceled", M50="Reject", M50="Rejected", K50="Cancel", K50="Canceled", K50="Reject", K50="Rejected", L50="Cancel", L50="Canceled", L50="Reject", L50="Rejected"), "Cancel / Rejected", AND(OR(J50="Perbaikan_Asset"), OR(M50="KSO Pending")), "KSO Need Send", TRUE, "Waiting Approval" )} -> Waiting Approval | P50: 22/08/2026 | Q50: {=_xlfn.IFS( OR(M50="Cancel", M50="Canceled", M50="Reject", M50="Rejected", K50="Cancel", K50="Canceled", K50="Reject", K50="Rejected", L50="Cancel", L50="Canceled", L50="Reject", L50="Rejected"), "Cancel / Rejected", P50<>"", "MSS Done Send", N50="MSS Need Send", "MSS Need Send", TRUE, "Waiting Approval" )} -> MSS Done Send | S50: {=_xlfn.IFS( OR(M50="Cancel", M50="Canceled", M50="Reject", M50="Rejected", K50="Cancel", K50="Canceled", K50="Reject", K50="Rejected", L50="Cancel", L50="Canceled", L50="Reject", L50="Rejected"), "Cancel / Rejected", R50<>"", "KSO Done Send", Q50="MSS Need Send", "MSS Need Send", O50="KSO Need Send", "KSO Need Send", TRUE, "Waiting Approval" )} -> Waiting Approval
